TRYING_TO_LOAD_RANDOM_DATASET Signal_40_D_0_linear_4_exp_2.0_0 data/ARTIFICIAL_DATA/40/Signal_40_D_0_linear_4_exp_2.0_0
LAOD_FAILED_TRYING_TO_GENERATE_RANDOM_DATASET Signal_40_D_0_linear_4_exp_2.0_0
GENERATING_RANDOM_DATASET Signal_40_D_0_linear_4_exp_2.0_0
TREND 0.0976270078546495 0.43037873274483895 0.20552675214328775
Traceback (most recent call last):
  File "<frozen importlib._bootstrap>", line 1072, in _find_spec
AttributeError: '_SixMetaPathImporter' object has no attribute 'find_spec'

During handling of the above exception, another exception occurred:

Traceback (most recent call last):
  File "/home/antoine/dev/python/packages/timeseries/pyaf/tests/bugs/test_artificial_bug_2.py", line 63, in <module>
    dataset = tsds.generate_random_TS(N = 40 , FREQ = 'D', seed = 0, trendtype = "linear", cycle_length = 4, transform = "exp", sigma = 2.0, exog_count = 0);
              ^^^^^^^^^^^^^^^^^^^^^^^^^^^^^^^^^^^^^^^^^^^^^^^^^^^^^^^^^^^^^^^^^^^^^^^^^^^^^^^^^^^^^^^^^^^^^^^^^^^^^^^^^^^^^^^^^^^^^^^^^^^^^^^^^^^^^^^^^^^^^^
  File "/home/antoine/dev/python/packages/timeseries/pyaf/pyaf/Bench/TS_datasets.py", line 334, in generate_random_TS
    tsspec = generate_random_TS_real(N , FREQ, seed, trendtype, cycle_length, transform, sigma, exog_count, ar_order)
             ^^^^^^^^^^^^^^^^^^^^^^^^^^^^^^^^^^^^^^^^^^^^^^^^^^^^^^^^^^^^^^^^^^^^^^^^^^^^^^^^^^^^^^^^^^^^^^^^^^^^^^^^
  File "/home/antoine/dev/python/packages/timeseries/pyaf/pyaf/Bench/TS_datasets.py", line 392, in generate_random_TS_real
    df_train['Signal'] = apply_transform(pos_signal , transform)
                         ^^^^^^^^^^^^^^^^^^^^^^^^^^^^^^^^^^^^^^^
  File "/home/antoine/dev/python/packages/timeseries/pyaf/pyaf/Bench/TS_datasets.py", line 282, in apply_transform
    import pyaf.TS.Signal_Transformation as tstransf
  File "/home/antoine/dev/python/packages/timeseries/pyaf/pyaf/TS/Signal_Transformation.py", line 13, in <module>
    import sklearn.preprocessing
  File "/home/antoine/.local/lib/python3.11/site-packages/sklearn/__init__.py", line 87, in <module>
    from .base import clone
  File "/home/antoine/.local/lib/python3.11/site-packages/sklearn/base.py", line 19, in <module>
    from .utils import _IS_32BIT
  File "/home/antoine/.local/lib/python3.11/site-packages/sklearn/utils/__init__.py", line 16, in <module>
    from scipy.sparse import issparse
  File "/usr/lib/python3/dist-packages/scipy/__init__.py", line 63, in <module>
    from . import _distributor_init
  File "/usr/lib/python3/dist-packages/scipy/_distributor_init.py", line 16, in <module>
    from . import _distributor_init_local  # noqa: F401
    ^^^^^^^^^^^^^^^^^^^^^^^^^^^^^^^^^^^^^
  File "<frozen importlib._bootstrap>", line 1176, in _find_and_load
  File "<frozen importlib._bootstrap>", line 1138, in _find_and_load_unlocked
  File "<frozen importlib._bootstrap>", line 1074, in _find_spec
  File "<frozen importlib._bootstrap>", line 1047, in _find_spec_legacy
ImportWarning: _SixMetaPathImporter.find_spec() not found; falling back to find_module()
EXECUTION_TIME_DETAIL = {'CMD':'timeout 480 python tests/bugs/test_artificial_bug_2.py', 'ElapsedTimeSecs':(0.69, 0.09, 0.59), 'MAX_MEM_KB':73592, 'CPU_PRCNT':'99%', 'FILES_IN':0, 'FILES_OUT':8, 'EXIT_STATUS':1}
